<?xml version="1.0" ?>
<!-- =================================================================================== -->
<!-- |    This document was autogenerated by xacro from my_robo_simulation.xacro       | -->
<!-- |    EDITING THIS FILE BY HAND IS NOT RECOMMENDED                                 | -->
<!-- =================================================================================== -->
<robot name="robot_name">
  <!--===== Defining all colours here =====-->
  <material name="Orange">
    <color rgba="0.5 0.2 0.0 1"/>
  </material>
  <material name="Yellow">
    <color rgba="0.5 0.5 0.0 1"/>
  </material>
  <material name="Red">
    <color rgba="0.5 0.0 0.0 1"/>
  </material>
  <material name="Blue">
    <color rgba="0.0 0.0 0.4 1"/>
  </material>
  <material name="Green">
    <color rgba="0.0 0.4 0.0 1"/>
  </material>
  <material name="White">
    <color rgba="1 1 1 1"/>
  </material>
  <material name="grey">
    <color rgba="0.108 0.122 0.137 1"/>
  </material>
  <!--BASE FOOTPRINT-->
  <link name="base_footprint"/>
  <!--========================================== BASE LINK ==========================================-->
  <link name="base_link">
    <inertial>
      <origin xyz="0 0 0.033" rpy="0 0 0"/>
      <mass value="8.2573504e-01"/>
      <inertia ixx="2.2124416e-03" ixy="-1.2294101e-05" ixz="3.4938785e-05"
               iyy="2.1193702e-03" iyz="-5.0120904e-06"
               izz="2.0064271e-03" />
    </inertial>
    <visual>
      <origin rpy="0 0 0" xyz="0 0 0.033"/>
      <geometry>
        <mesh filename="package://robot/urdf/meshes/base.stl" scale="0.1 0.1 0.1"/>
      </geometry>
      <material name="White"/>
    </visual>
    <collision>
      <origin rpy="0 0 0" xyz="0 0 0.033"/>
      <geometry>
        <mesh filename="package://robot/urdf/meshes/base.stl" scale="0.1 0.1 0.1"/>
      </geometry>
    </collision>
  </link>
  <!--========================================== BASE JOINT ==========================================-->
  <joint name="base_joint" type="fixed">
    <origin rpy="0 0 0.02" xyz="0 0 0.0"/>
    <parent link="base_footprint"/>
    <child link="base_link"/>
    <axis xyz="0 0 0"/>
  </joint>
  <!--========================================== LEFT WHEEL LINK ==========================================-->
  <link name="left_wheel_link">
    <inertial>
      <origin xyz="0 0 0" />
      <mass value="2.8498940e-02" />
      <inertia ixx="1.1175580e-05" ixy="-4.2369783e-11" ixz="-5.9381719e-09"
               iyy="1.1192413e-05" iyz="-1.4400107e-11"
               izz="2.0712558e-05" />
      </inertial>
      <visual>
        <origin xyz="0 0 0" rpy="0 0 0" />
        <geometry>
          <cylinder length="0.06" radius="0.065" />
        </geometry>
        <material name="Red" />
      </visual>
      <collision>
        <origin xyz="0 0 0" rpy="0 0 0" />
        <geometry>
          <cylinder length="0.06" radius="0.065" />
        </geometry>
      </collision>
  </link>
  <gazebo reference="left_wheel_link">
    <mu1>0.9</mu1>
    <mu2>0.9</mu2>
    <kp>100000000</kp>
    <kd>1</kd>
    <minDepth>0.001</minDepth>
    <maxVel>0.1</maxVel>
    <fdir1>1 0 0</fdir1>
    <implicitSpringDamper>true</implicitSpringDamper>
    <material>Gazebo/FlatBlack</material>
  </gazebo>
  <!--========================================== LEFT WHEEL JOINT ==========================================-->
  <joint name="left_wheel_joint" type="continuous">
    <origin rpy="1.571 0.0 0" xyz="0.0 0.158075 0.065"/>
    <parent link="base_link"/>
    <child link="left_wheel_link"/>
    <axis xyz="0 0 -1"/>
    <limit effort="100.0" velocity="100.0"/>
    <joint_properties damping="0.0" fiction="0.0"/>
  </joint>
  <!--transmission name="left_wheel_trans" type="SimpleTransmission">
    <type>transmission_interface/SimpleTransmission</type>
    <actuator name="left_wheel_motor">
      <mechanicalReduction>1</mechanicalReduction>
    </actuator>
    <joint name="left_wheel_joint">
      <hardwareInterface>VelocityJointInterface</hardwareInterface>
    </joint>
  </transmission-->
  <!--========================================== RIGHT WHEEL LINK ==========================================-->
  <link name="right_wheel_link">
    <inertial>
      <origin xyz="0 0 0" />
      <mass value="2.8498940e-02" />
      <inertia ixx="1.1175580e-05" ixy="-4.2369783e-11" ixz="-5.9381719e-09"
               iyy="1.1192413e-05" iyz="-1.4400107e-11"
               izz="2.0712558e-05" />
      </inertial>
      <visual>
        <origin xyz="0 0 0" rpy="0 0 0" />
        <geometry>
          <cylinder length="0.06" radius="0.065" />
        </geometry>
        <material name="Red" />
      </visual>
      <collision>
        <origin xyz="0 0 0" rpy="0 0 0" />
        <geometry>
          <cylinder length="0.06" radius="0.065" />
        </geometry>
      </collision>
  </link>
  <gazebo reference="right_wheel_link">
    <mu1>0.9</mu1>
    <mu2>0.9</mu2>
    <kp>100000000</kp>
    <kd>1</kd>
    <minDepth>0.001</minDepth>
    <maxVel>0.1</maxVel>
    <fdir1>1 0 0</fdir1>
    <implicitSpringDamper>true</implicitSpringDamper>
    <material>Gazebo/FlatBlack</material>
  </gazebo>
  <!--========================================== RIGHT WHEEL JOINT ==========================================-->
  <joint name="right_wheel_joint" type="continuous">
    <origin rpy="-1.571 0.0 0" xyz="0.0 -0.158075 0.065"/>
    <parent link="base_link"/>
    <child link="right_wheel_link"/>
    <axis xyz="0 0 1"/>
    <limit effort="100.0" velocity="100.0"/>
    <joint_properties damping="0.0" fiction="0.0"/>
  </joint>
  <!--transmission name="right_wheel_trans" type="SimpleTransmission">
  <type>transmission_interface/SimpleTransmission</type>
  <actuator name="right_wheel_motor">
    <mechanicalReduction>1</mechanicalReduction>
  </actuator>
  <joint name="right_wheel_joint">
    <hardwareInterface>VelocityJointInterface</hardwareInterface>
  </joint>
</transmission-->
  <!--=============================================== FRONT CASTOR WHEEL LINK ===============================================-->
  <link name="front_castor_wheel_link">
    <collision>
      <origin xyz="0 0.025 0" rpy="0 0 0"/>
      <geometry>
        <box size="0.030 0.009 0.020"/>
      </geometry>
    </collision>

    <inertial>
      <origin xyz="0 0 0" />
      <mass value="0.005" />
      <inertia ixx="0.001" ixy="0.0" ixz="0.0"
               iyy="0.001" iyz="0.0"
               izz="0.001" />
    </inertial>
  </link>
  <gazebo reference="front_castor_wheel_link">
    <mu1>0.1</mu1>
    <mu2>0.1</mu2>
    <kp>1000000.0</kp>
    <kd>100.0</kd>
    <minDepth>0.001</minDepth>
    <maxVel>1.0</maxVel>
    <material>Gazebo/FlatBlack</material>
  </gazebo>
  <!--============================================ FRONT CASTOR WHEEL JOINT ============================================-->
  <joint name="front_castor_wheel_joint" type="fixed">
    <origin rpy="0.0 0.0 0.0" xyz="0.2 0.0 0.0252"/>
    <parent link="base_link"/>
    <child link="front_castor_wheel_link"/>
    <axis xyz="0 0 0"/>
  </joint>
  <!--=============================================== REAR CASTOR WHEEL LINK ===============================================-->
  <link name="rear_castor_wheel_link">
    <collision>
      <origin xyz="0 0.025 0" rpy="0 0 0"/>
      <geometry>
        <box size="0.030 0.009 0.020"/>
      </geometry>
    </collision>

    <inertial>
      <origin xyz="0 0 0" />
      <mass value="0.005" />
      <inertia ixx="0.001" ixy="0.0" ixz="0.0"
               iyy="0.001" iyz="0.0"
               izz="0.001" />
    </inertial>
  </link>
  <gazebo reference="rear_castor_wheel_link">
    <mu1>0.1</mu1>
    <mu2>0.1</mu2>
    <kp>1000000.0</kp>
    <kd>100.0</kd>
    <minDepth>0.001</minDepth>
    <maxVel>1.0</maxVel>
    <material>Gazebo/FlatBlack</material>
  </gazebo>
  <!--============================================ REAR CASTOR WHEEL JOINT ============================================-->
  <joint name="rear_castor_wheel_joint" type="fixed">
    <origin rpy="0.0 0.0 0.0" xyz="-0.2 0.0 0.0252"/>
    <parent link="base_link"/>
    <child link="rear_castor_wheel_link"/>
    <axis xyz="0 0 0"/>
  </joint>
  <!--========================================== LASER LINK ==========================================-->
  <link name="laser_link">
    <inertial>
      <mass value="0.114" />
      <origin xyz="0 0 0" />
      <inertia ixx="0.001" ixy="0.0" ixz="0.0"
               iyy="0.001" iyz="0.0"
               izz="0.001" />
    </inertial>
    <visual>
      <origin rpy="0 0 0" xyz="0 0 0"/>
      <geometry>
        <mesh filename="package://robot/urdf/meshes/ridar.stl" scale="0.1 0.1 0.1"/>
      </geometry>
      <material name="Red"/>
    </visual>
    <collision>
      <origin rpy="0 0 0" xyz="0 0 0"/>
      <geometry>
        <mesh filename="package://robot/urdf/meshes/ridar.stl" scale="0.1 0.1 0.1"/>
      </geometry>
    </collision>
  </link>
  <!--========================================== LASER JOINT ==========================================-->
  <joint name="laser_joint" type="fixed">
    <origin rpy="0.0 0.0 0" xyz="0.125 0.0 0.2"/>
    <parent link="base_link"/>
    <child link="laser_link"/>
    <axis xyz="0 0 0"/>
  </joint>
  <!--========================================== GAZEBO TAGS ==========================================-->
  <gazebo reference="base_link">
    <material>Gazebo/Blue</material>
  </gazebo>
  <gazebo reference="robot_body_link">
    <material>Gazebo/Orange</material>
  </gazebo>
  <gazebo reference="right_wheel_link">
    <material>Gazebo/Red</material>
  </gazebo>
  <gazebo reference="left_wheel_link">
    <material>Gazebo/Red</material>
  </gazebo>
  <gazebo reference="front_castor_wheel_link">
    <material>Gazebo/Red</material>
  </gazebo>
  <gazebo reference="rear_castor_wheel_link">
    <material>Gazebo/Red</material>
  </gazebo>
  <gazebo reference="laser_link">
    <material>Gazebo/Green</material>
  </gazebo>
  <!--========================================== DIFF DRIVE PLUGIN - GAZEBO ==========================================-->
  <gazebo>
    <plugin filename="libgazebo_ros_diff_drive.so" name="differential_drive_controller">
      <alwaysOn>true</alwaysOn>
      <!-- Plugin update rate in Hz -->
      <updateRate>100</updateRate>
      <!-- Name of left joint, defaults to `left_joint` -->
      <leftJoint>left_wheel_joint</leftJoint>
      <!-- Name of right joint, defaults to `right_joint` -->
      <rightJoint>right_wheel_joint</rightJoint>
      <!-- The distance from the center of one wheel to the other, in meters, defaults to 0.34 m -->
      <wheelSeparation>0.31615</wheelSeparation>
      <!-- Diameter of the wheels, in meters, defaults to 0.15 m -->
      <wheelDiameter>0.13</wheelDiameter>
      <!-- Maximum torque which the wheels can produce, in Nm, defaults to 5 Nm -->
      <wheelTorque>10</wheelTorque>
      <!-- Topic to receive geometry_msgs/Twist message commands, defaults to `cmd_vel` -->
      <commandTopic>cmd_vel</commandTopic>
      <!-- Topic to publish nav_msgs/Odometry messages, defaults to `odom` -->
      <odometryTopic>odom</odometryTopic>
      <!-- Odometry frame, defaults to `odom` -->
      <odometryFrame>odom</odometryFrame>
      <!-- Robot frame to calculate odometry from, defaults to `base_footprint` -->
      <robotBaseFrame>base_footprint</robotBaseFrame>
      <!-- Odometry source, 0 for ENCODER, 1 for WORLD, defaults to WORLD -->
      <odometrySource>1</odometrySource>
      <!-- Set to true to publish transforms for the wheel links, defaults to false -->
      <publishWheelTF>false</publishWheelTF>
      <!-- Set to true to publish transforms for the odometry, defaults to true -->
      <publishOdom>true</publishOdom>
      <!-- Set to true to publish sensor_msgs/JointState on /joint_states for the wheel joints, defaults to false -->
      <publishWheelJointState>false</publishWheelJointState>
      <!-- Set to true to swap right and left wheels, defaults to true -->
      <legacyMode>false</legacyMode>
    </plugin>
  </gazebo>
  <!--========================================== LIDAR PLUGIN - GAZEBO ==========================================-->
  <!--Sample size of 4000 (original value of RPLidarA1M8) gives an error-->
  <gazebo reference="laser_link">
    <!--sensor type="gpu_ray" name="laser"-->
    <sensor name="laser" type="ray">
      <pose>0 0 0 0 0 0</pose>
      <visualize>false</visualize>
      <update_rate>40</update_rate>
      <ray>
        <scan>
          <horizontal>
            <samples>720</samples>
            <resolution>1</resolution>
            <min_angle>0</min_angle>
            <max_angle>6.28</max_angle>
          </horizontal>
        </scan>
        <range>
          <min>0.1</min>
          <max>6</max>
          <resolution>0.1</resolution>
        </range>
      </ray>
      <!--plugin name="gpu_laser" filename="libgazebo_ros_gpu_laser.so"-->
      <plugin filename="libgazebo_ros_laser.so" name="gpu_laser">
        <topicName>/scan</topicName>
        <frameName>laser_link</frameName>
      </plugin>
    </sensor>
  </gazebo>
  <!--========================================== JOINT STATE PUBLISHER PLUGIN - GAZEBO ==========================================-->
  <!--gazebo>
        <plugin name="joint_state_publisher"
                filename="libgazebo_ros_joint_state_publisher.so">
            <jointName>left_wheel_joint, right_wheel_joint, castor_wheel_joint</jointName>
        </plugin>
    </gazebo-->
</robot>
