<?xml version="1.0"?>	
<robot name="robot">

  <!--BASE FOOTPRINT-->
  <link name="base_footprint" />

  <!--===== Defining all colours here =====-->
  <material name="Orange">
    <color rgba="0.5 0.2 0.0 1" />
  </material>
  <material name="Yellow">
    <color rgba="0.5 0.5 0.0 1" />
  </material>
  <material name="Red">
    <color rgba="0.5 0.0 0.0 1" />
  </material>
  <material name="Blue">
    <color rgba="0.0 0.0 0.4 1" />
  </material>
  <material name="Green">
    <color rgba="0.0 0.4 0.0 1" />
  </material>


  <!--========================================== BASE LINK ==========================================-->
  <link name="base_link">
    <inertial>
      <origin xyz="0 0 0.033" rpy="0 0 0"/>
      <mass value="8.2573504e-01"/>
      <inertia ixx="2.2124416e-03" ixy="-1.2294101e-05" ixz="3.4938785e-05"
               iyy="2.1193702e-03" iyz="-5.0120904e-06"
               izz="2.0064271e-03" />
    </inertial>
    <visual>
      <origin rpy="0 0 0" xyz="0 0 0.033"/>
      <geometry>
        <mesh filename="package://robot/urdf/meshes/base.stl" scale="0.1 0.1 0.1"/>
      </geometry>
      <material name="White"/>
    </visual>
    <collision>
      <origin rpy="0 0 0" xyz="0 0 0.033"/>
      <geometry>
        <mesh filename="package://robot/urdf/meshes/base.stl" scale="0.1 0.1 0.1"/>
      </geometry>
    </collision>
  </link>


  <!--========================================== BASE JOINT ==========================================-->
  <joint name="base_joint" type="fixed">
    <origin xyz="0 0 0.0335" rpy="0 0 0" />
    <parent link="base_footprint" />
    <child link="base_link" />
    <axis xyz="0 0 0" />
  </joint>


 

  


  <!--========================================== LEFT WHEEL LINK ==========================================-->
  <link name="left_wheel_link">
    <inertial>
      <origin xyz="0 0 0" />
      <mass value="2.8498940e-02" />
      <inertia ixx="1.1175580e-05" ixy="-4.2369783e-11" ixz="-5.9381719e-09"
               iyy="1.1192413e-05" iyz="-1.4400107e-11"
               izz="2.0712558e-05" />
      </inertial>
      <visual>
        <origin xyz="0 0 0" rpy="0 0 0" />
        <geometry>
          <cylinder length="0.06" radius="0.065" />
        </geometry>
        <material name="Red" />
      </visual>
      <collision>
        <origin xyz="0 0 0" rpy="0 0 0" />
        <geometry>
          <cylinder length="0.06" radius="0.065" />
        </geometry>
      </collision>
  </link>

  <!--========================================== LEFT WHEEL JOINT ==========================================-->
  <joint name="left_wheel_joint" type="continuous">
    <origin rpy="1.571 0.0 0" xyz="0.0 0.158075 0.065"/>
    <parent link="base_link"/>
    <child link="left_wheel_link"/>
    <axis xyz="0 0 -1"/>
    <limit effort="100.0" velocity="100.0"/>
    <joint_properties damping="0.0" fiction="0.0"/>
  </joint>

  <transmission name="left_wheel_trans" type="SimpleTransmission">
    <type>transmission_interface/SimpleTransmission</type>
    <actuator name="left_wheel_motor">
      <mechanicalReduction>1</mechanicalReduction>
    </actuator>
    <joint name="left_wheel_joint">
      <hardwareInterface>VelocityJointInterface</hardwareInterface>
    </joint>
  </transmission>


<!--========================================== RIGHT WHEEL LINK ==========================================-->
<link name="right_wheel_link">
  <inertial>
    <origin xyz="0 0 0" />
    <mass value="2.8498940e-02" />
    <inertia ixx="1.1175580e-05" ixy="-4.2369783e-11" ixz="-5.9381719e-09"
             iyy="1.1192413e-05" iyz="-1.4400107e-11"
             izz="2.0712558e-05" />
    </inertial>
    <visual>
      <origin xyz="0 0 0" rpy="0 0 0" />
      <geometry>
        <cylinder length="0.06" radius="0.065" />
      </geometry>
      <material name="Red" />
    </visual>
    <collision>
      <origin xyz="0 0 0" rpy="0 0 0" />
      <geometry>
        <cylinder length="0.06" radius="0.065" />
      </geometry>
    </collision>
</link>

<!--========================================== RIGHT WHEEL JOINT ==========================================-->
<joint name="right_wheel_joint" type="continuous">
  <origin rpy="-1.571 0.0 0" xyz="0.0 -0.158075 0.065"/>
  <parent link="base_link"/>
  <child link="right_wheel_link"/>
  <axis xyz="0 0 1"/>
  <limit effort="100.0" velocity="100.0"/>
  <joint_properties damping="0.0" fiction="0.0"/>
</joint>

<transmission name="right_wheel_trans" type="SimpleTransmission">
  <type>transmission_interface/SimpleTransmission</type>
  <actuator name="right_wheel_motor">
    <mechanicalReduction>1</mechanicalReduction>
  </actuator>
  <joint name="right_wheel_joint">
    <hardwareInterface>VelocityJointInterface</hardwareInterface>
  </joint>
</transmission>



  <!--=============================================== FRONT CASTOR WHEEL LINK ===============================================-->
  <link name="front_castor_wheel_link">
    <link name="front_castor_wheel_link">
      <collision>
        <origin xyz="0 0.025 0" rpy="0 0 0"/>
        <geometry>
          <box size="0.030 0.009 0.020"/>
        </geometry>
      </collision>
  
      <inertial>
        <origin xyz="0 0 0" />
        <mass value="0.005" />
        <inertia ixx="0.001" ixy="0.0" ixz="0.0"
                 iyy="0.001" iyz="0.0"
                 izz="0.001" />
      </inertial>
    </link>
  </link>

  <!--============================================ FRONT CASTOR WHEEL JOINT ============================================-->
  <joint name="front_castor_wheel_joint" type="fixed">
    <origin rpy="0.0 0.0 0.0" xyz="0.2 0.0 0.0252"/>
    <parent link="base_link"/>
    <child link="front_castor_wheel_link"/>
    <axis xyz="0 0 0"/>
  </joint>


  <!--=============================================== REAR CASTOR WHEEL LINK ===============================================-->
  <link name="rear_castor_wheel_link">
    <collision>
      <origin xyz="0 0.025 0" rpy="0 0 0"/>
      <geometry>
        <box size="0.030 0.009 0.020"/>
      </geometry>
    </collision>

    <inertial>
      <origin xyz="0 0 0" />
      <mass value="0.005" />
      <inertia ixx="0.001" ixy="0.0" ixz="0.0"
               iyy="0.001" iyz="0.0"
               izz="0.001" />
    </inertial>
  </link>

  <!--============================================ REAR CASTOR WHEEL JOINT ============================================-->
  <joint name="rear_castor_wheel_joint" type="fixed">
    <origin rpy="0.0 0.0 0.0" xyz="-0.2 0.0 0.0252"/>
    <parent link="base_link"/>
    <child link="rear_castor_wheel_link"/>
    <axis xyz="0 0 0"/>
  </joint>


  <!--========================================== LASER LINK ==========================================-->
  <link name="laser_link">
    <inertial>
      <mass value="0.114" />
      <origin xyz="0 0 0" />
      <inertia ixx="0.001" ixy="0.0" ixz="0.0"
               iyy="0.001" iyz="0.0"
               izz="0.001" />
    </inertial>
    <visual>
      <origin rpy="0 0 0" xyz="0 0 0"/>
      <geometry>
        <mesh filename="package://robot/urdf/meshes/ridar.stl" scale="0.1 0.1 0.1"/>
      </geometry>
      <material name="Red"/>
    </visual>
    <collision>
      <origin rpy="0 0 0" xyz="0 0 0"/>
      <geometry>
        <mesh filename="package://robot/urdf/meshes/ridar.stl" scale="0.1 0.1 0.1"/>
      </geometry>
    </collision>
  </link>

  <!--========================================== LASER JOINT ==========================================-->
  <joint name="laser_joint" type="fixed">
    <origin rpy="0.0 0.0 0" xyz="0.125 0.0 0.2"/>
    <parent link="base_link"/>
    <child link="laser_link"/>
    <axis xyz="0 0 0"/>
  </joint>


</robot>
